<?xml version="1.0" encoding="utf-8"?>

<robot name="hand4f">

  <material name="black">
    <color rgba="0 0 0 1"/>
  </material>
  <material name="gray">
    <color rgba="0.1 0.1 0.1 1"/>
  </material>
  <material name="lightgray">
    <color rgba="0.8 0.8 0.8 1"/>
  </material>


  <!-- Base Link -->
  <link name="base_link">
    <origin rpy="0.0 0.0 0.0" xyz="0.0 0.0 0.0"/>
  </link>


  <!-- Hand Plate -->
  <link name="hand_plate">
    <visual>
      <origin xyz="0 0 0" rpy="0 0 0" />
      <geometry>
        <cylinder radius="0.14" length="0.02" />
      </geometry>
    </visual>
    <collision>
      <origin xyz="0 0 0" rpy="0 0 0" />
      <geometry>
        <cylinder radius="0.14" length="0.02" />
      </geometry>
    </collision>
  </link>
  <joint name="hand_plate_joint" type="fixed">
    <origin xyz="0 0 0" rpy="0 0 0" />
    <parent link="base_link" />
    <child link="hand_plate" />
  </joint>


  <!-- Finger 1 -->
  <link name="finger1_proximal">
    <visual>
      <origin rpy="0 0 0" xyz="0 0 0" />
      <geometry>
        <mesh filename="package://hand/urdf/meshes/visual/proximal.dae"/>
      </geometry>
      <material name="gray"/>
    </visual>
    <collision>
      <origin rpy="0 0 0" xyz="0 0 0" />
      <geometry>
        <mesh filename="package://hand/urdf/meshes/collision/proximal.obj"/>
      </geometry>
    </collision>
    <inertial>
      <mass value="0.09313"/>
    </inertial>
  </link>
  <link name="finger1_middle">
    <visual>
      <origin rpy="0 0 0" xyz="0 0 0" />
      <geometry>
        <mesh filename="package://hand/urdf/meshes/visual/middle.dae"/>
      </geometry>
      <material name="gray"/>
    </visual>
    <collision>
      <origin rpy="0 0 0" xyz="0 0 0" />
      <geometry>
        <mesh filename="package://hand/urdf/meshes/collision/middle.obj"/>
      </geometry>
    </collision>
    <inertial>
      <mass value="0.09930"/>
    </inertial>
  </link>
  <link name="finger1_distal">
    <visual>
      <origin rpy="0 3.14159265359 0" xyz="0 0 0"/>
      <geometry>
        <mesh filename="package://hand/urdf/meshes/visual/distal.dae"/>
      </geometry>
      <material name="lightgray"/>
    </visual>
    <collision name="tip">
      <origin rpy="-1.57079633 1.57079633 0" xyz="0.0 0.1043 0.0"/>
      <geometry>
        <sphere radius="0.019"/>
      </geometry>
    </collision>
    <collision name="body">
      <origin rpy="-1.57079633 1.57079633 0" xyz="0 0.06358 0.0"/>
      <geometry>
        <cylinder length="0.0815" radius="0.019"/>
      </geometry>
    </collision>
    <inertial>
      <mass value="0.09268"/>
      <inertia ixx="0.01" ixy="0.00" ixz="0.00" iyy="0.01" iyz="0.0" izz="0.01"/>
      <!-- inertia is recomputed when loading asset  -->
    </inertial>
  </link>
  <link name="finger1_distal_tip">
  </link>
  <joint name="finger1_proximal_joint" type="revolute">
    <parent link="hand_plate"/>
    <child link="finger1_proximal"/>
    <origin rpy="1.5707963267948966 0 -1.5707963267948966" xyz="-0.110 0.0 0.0"/>
    <axis xyz="0 1 0"/>
    <limit effort="4" velocity="1.0" lower="-1.0" upper="1.0"/>
  </joint>
  <joint name="finger1_middle_joint" type="revolute">
    <parent link="finger1_proximal"/>
    <child link="finger1_middle"/>
    <origin rpy="0 0 0" xyz="0 0.0655 0"/>
    <axis xyz="-1 0 0"/>
    <limit effort="4" velocity="1.0" lower="0.0" upper="1.0"/>
  </joint>
  <joint name="finger1_distal_joint" type="revolute">
    <parent link="finger1_middle"/>
    <child link="finger1_distal"/>
    <origin rpy="0 0 0" xyz="0 0.069 0"/>
    <axis xyz="-1 0 0"/>
    <limit effort="4" velocity="1.0" lower="0.0" upper="1.0"/>
  </joint>
  <joint name="finger1_distal_tip_joint" type="fixed">
    <parent link="finger1_distal"/>
    <child link="finger1_distal_tip"/>
    <origin rpy="-1.57079633 1.57079633 0" xyz="0.0 0.1035 0.0"/>
  </joint>


  <!-- Finger 2 -->
  <link name="finger2_proximal">
    <visual>
      <origin rpy="0 0 0" xyz="0 0 0" />
      <geometry>
        <mesh filename="package://hand/urdf/meshes/visual/proximal.dae"/>
      </geometry>
      <material name="gray"/>
    </visual>
    <collision>
      <origin rpy="0 0 0" xyz="0 0 0" />
      <geometry>
        <mesh filename="package://hand/urdf/meshes/collision/proximal.obj"/>
      </geometry>
    </collision>
    <inertial>
      <mass value="0.09313"/>
    </inertial>
  </link>
  <link name="finger2_middle">
    <visual>
      <origin rpy="0 0 0" xyz="0 0 0" />
      <geometry>
        <mesh filename="package://hand/urdf/meshes/visual/middle.dae"/>
      </geometry>
      <material name="gray"/>
    </visual>
    <collision>
      <origin rpy="0 0 0" xyz="0 0 0" />
      <geometry>
        <mesh filename="package://hand/urdf/meshes/collision/middle.obj"/>
      </geometry>
    </collision>
    <inertial>
      <mass value="0.09930"/>
    </inertial>
  </link>
  <link name="finger2_distal">
    <visual>
      <origin rpy="0 3.14159265359 0" xyz="0 0 0" />
      <geometry>
        <mesh filename="package://hand/urdf/meshes/visual/distal.dae"/>
      </geometry>
      <material name="lightgray"/>
    </visual>
    <collision name="tip">
      <origin rpy="-1.57079633 1.57079633 0" xyz="0.0 0.1043 0.0"/>
      <geometry>
        <sphere radius="0.019"/>
      </geometry>
    </collision>
    <collision name="body">
      <origin rpy="-1.57079633 1.57079633 0" xyz="0 0.06358 0.0"/>
      <geometry>
        <cylinder length="0.0815" radius="0.019"/>
      </geometry>
    </collision>
    <inertial>
      <mass value="0.09268"/>
      <inertia ixx="0.01" ixy="0.00" ixz="0.00" iyy="0.01" iyz="0.0" izz="0.01"/>
      <!-- inertia is recomputed when loading asset  -->
    </inertial>
  </link>
  <link name="finger2_distal_tip">
  </link>
  <joint name="finger2_proximal_joint" type="revolute">
    <parent link="hand_plate"/>
    <child link="finger2_proximal"/>
    <origin rpy="1.5707963267948966 0 2.35" xyz="0.077 0.077 0.0"/>
    <axis xyz="0 1 0"/>
    <limit effort="4" velocity="1.0" lower="-1.0" upper="1.0"/>
  </joint>
  <joint name="finger2_middle_joint" type="revolute">
    <parent link="finger2_proximal"/>
    <child link="finger2_middle"/>
    <origin rpy="0 0 0" xyz="0 0.0655 0"/>
    <axis xyz="-1 0 0"/>
    <limit effort="4" velocity="1.0" lower="0.0" upper="1.0"/>
  </joint>
  <joint name="finger2_distal_joint" type="revolute">
    <parent link="finger2_middle"/>
    <child link="finger2_distal"/>
    <origin rpy="0 0 0" xyz="0 0.069 0"/>
    <axis xyz="-1 0 0"/>
    <limit effort="4" velocity="1.0" lower="0.0" upper="1.0"/>
  </joint>
  <joint name="finger2_distal_tip_joint" type="fixed">
    <parent link="finger2_distal"/>
    <child link="finger2_distal_tip"/>
    <origin rpy="-1.57079633 1.57079633 0" xyz="0.0 0.1035 0.0"/>
  </joint>


  <!-- Finger 3 -->
  <link name="finger3_proximal">
     <visual>
      <origin rpy="0 0 0" xyz="0 0 0" />
      <geometry>
        <mesh filename="package://hand/urdf/meshes/visual/proximal.dae"/>
      </geometry>
      <material name="gray"/>
    </visual>
    <collision>
      <origin rpy="0 0 0" xyz="0 0 0" />
      <geometry>
        <mesh filename="package://hand/urdf/meshes/collision/proximal.obj"/>
      </geometry>
    </collision>
     <inertial>
      <mass value="0.09313"/>
    </inertial>
  </link>
  <link name="finger3_middle">
    <visual>
      <origin rpy="0 0 0" xyz="0 0 0" />
      <geometry>
        <mesh filename="package://hand/urdf/meshes/visual/middle.dae"/>
      </geometry>
      <material name="gray"/>
    </visual>
    <collision>
      <origin rpy="0 0 0" xyz="0 0 0" />
      <geometry>
        <mesh filename="package://hand/urdf/meshes/collision/middle.obj"/>
      </geometry>
    </collision>
    <inertial>
      <mass value="0.09930"/>
    </inertial>
  </link>
  <link name="finger3_distal">
    <visual>
      <origin rpy="0 3.14159265359 0" xyz="0 0 0" />
      <geometry>
        <mesh filename="package://hand/urdf/meshes/visual/distal.dae"/>
      </geometry>
      <material name="lightgray"/>
    </visual>
    <collision name="tip">
      <origin rpy="-1.57079633 1.57079633 0" xyz="0.0 0.1043 0.0"/>
      <geometry>
        <sphere radius="0.019"/>
      </geometry>
    </collision>
    <collision name="body">
      <origin rpy="-1.57079633 1.57079633 0" xyz="0 0.06358 0.0"/>
      <geometry>
        <cylinder length="0.0815" radius="0.019"/>
      </geometry>
    </collision>
    <inertial>
      <mass value="0.09268"/>
      <inertia ixx="0.01" ixy="0.00" ixz="0.00" iyy="0.01" iyz="0.0" izz="0.01"/>
      <!-- inertia is recomputed when loading asset  -->
    </inertial>
  </link>
  <link name="finger3_distal_tip">
  </link>
  <joint name="finger3_proximal_joint" type="revolute">
    <parent link="hand_plate"/>
    <child link="finger3_proximal"/>
    <origin rpy="1.5707963267948966 0 1.57" xyz="0.110  0.0  0.0"/>
    <axis xyz="0 1 0"/>
    <limit effort="4" velocity="1.0" lower="-1.0" upper="1.0"/>
  </joint>
  <joint name="finger3_middle_joint" type="revolute">
    <parent link="finger3_proximal"/>
    <child link="finger3_middle"/>
    <origin rpy="0 0 0" xyz="0 0.0655 0"/>
    <axis xyz="-1 0 0"/>
    <limit effort="4" velocity="1.0" lower="0.0" upper="1.0"/>
  </joint>
  <joint name="finger3_distal_joint" type="revolute">
    <parent link="finger3_middle"/>
    <child link="finger3_distal"/>
    <origin rpy="0 0 0" xyz="0 0.069 0"/>
    <axis xyz="-1 0 0"/>
    <limit effort="4" velocity="1.0" lower="0.0" upper="1.0"/>
  </joint>
  <joint name="finger3_distal_tip_joint" type="fixed">
    <parent link="finger3_distal"/>
    <child link="finger3_distal_tip"/>
    <origin rpy="-1.57079633 1.57079633 0" xyz="0.0 0.1035 0.0"/>
  </joint>


  <!-- Finger 4 -->
  <link name="finger4_proximal">
     <visual>
      <origin rpy="0 0 0" xyz="0 0 0" />
      <geometry>
        <mesh filename="package://hand/urdf/meshes/visual/proximal.dae"/>
      </geometry>
      <material name="gray"/>
    </visual>
    <collision>
      <origin rpy="0 0 0" xyz="0 0 0" />
      <geometry>
        <mesh filename="package://hand/urdf/meshes/collision/proximal.obj"/>
      </geometry>
    </collision>
    <inertial>
      <mass value="0.09313"/>
    </inertial>
  </link>
  <link name="finger4_middle">
   <visual>
      <origin rpy="0 0 0" xyz="0 0 0" />
      <geometry>
        <mesh filename="package://hand/urdf/meshes/visual/middle.dae"/>
      </geometry>
      <material name="gray"/>
    </visual>
    <collision>
      <origin rpy="0 0 0" xyz="0 0 0" />
      <geometry>
        <mesh filename="package://hand/urdf/meshes/collision/middle.obj"/>
      </geometry>
    </collision>
    <inertial>
      <mass value="0.09930"/>
    </inertial>
  </link>
  <link name="finger4_distal">
    <visual>
      <origin rpy="0 3.14159265359 0" xyz="0 0 0" />
      <geometry>
        <mesh filename="package://hand/urdf/meshes/visual/distal.dae"/>
      </geometry>
      <material name="lightgray"/>
    </visual>
    <collision name="tip">
      <origin rpy="-1.57079633 1.57079633 0" xyz="0.0 0.1043 0.0"/>
      <geometry>
        <sphere radius="0.019"/>
      </geometry>
    </collision>
    <collision name="body">
      <origin rpy="-1.57079633 1.57079633 0" xyz="0 0.06358 0.0"/>
      <geometry>
        <cylinder length="0.0815" radius="0.019"/>
      </geometry>
    </collision>
    <inertial>
      <mass value="0.09268"/>
      <inertia ixx="0.01" ixy="0.00" ixz="0.00" iyy="0.01" iyz="0.0" izz="0.01"/>
      <!-- inertia is recomputed when loading asset  -->
    </inertial>
  </link>
  <link name="finger4_distal_tip">
  </link>
  <joint name="finger4_proximal_joint" type="revolute">
    <parent link="hand_plate"/>
    <child link="finger4_proximal"/>
    <origin rpy="1.5707963267948966 0 0.785" xyz="0.077 -0.077  0.0"/>
    <axis xyz="0 1 0"/>
    <limit effort="4" velocity="1.0" lower="-1.0" upper="1.0"/>
  </joint>
  <joint name="finger4_middle_joint" type="revolute">
    <parent link="finger4_proximal"/>
    <child link="finger4_middle"/>
    <origin rpy="0 0 0" xyz="0 0.0655 0"/>
    <axis xyz="-1 0 0"/>
    <limit effort="4" velocity="1.0" lower="0.0" upper="1.0"/>
  </joint>
  <joint name="finger4_distal_joint" type="revolute">
    <parent link="finger4_middle"/>
    <child link="finger4_distal"/>
    <origin rpy="0 0 0" xyz="0 0.069 0"/>
    <axis xyz="-1 0 0"/>
    <limit effort="4" velocity="1.0" lower="0.0" upper="1.0"/>
  </joint>
  <joint name="finger4_distal_tip_joint" type="fixed">
    <parent link="finger4_distal"/>
    <child link="finger4_distal_tip"/>
    <origin rpy="-1.57079633 1.57079633 0" xyz="0.0 0.1035 0.0"/>
  </joint>


</robot>